Workbook

Sheet Form Responses
A1: Timestamp | B1: Email Address | C1: NetID | D1: Responsible Team | E1: Current Status | F1: Photo Upload | G1: Issue Description | H1: Required Actions / Comments | I1: Email Tracking | J1: Deadline | K1: Cleared
A2: 45918.389 | B2: =CONCATENATE(C2,"@cornell.edu") -> Nhh5@cornell.edu | C2: Nhh5 | D2: steel bridge | E2: Yellow - Stewardship concern (Address at next scheduled meeting) | F2: https://drive.google.com/open?id=1o2qJINxEtIWecc01_T3hwMHrd5eQW7Di | G2: Housekeeping | H2: Move workbenches and materials At least a foot away from air tunnel | I2: Old | J2: =IFERROR(__xludf.DUMMYFUNCTION("IF(ISDATE(A2), DATE(YEAR(A2), MONTH(A2), DAY(A2)+ IFS(ISNUMBER(SEARCH(""Red"", E2)), 1, ISNUMBER(SEARCH(""Orange"", E2)), 3, ISNUMBER(SEARCH(""Yellow"", E2)), 10, ISNUMBER(SEARCH(""Ivory"", E2)), 21,TRUE, ""60"")), """")"),45928.0) -> 45928 | K2: 45931
A3: 45918.392 | B3: =CONCATENATE(C3,"@cornell.edu") -> Nhh5@cornell.edu | C3: Nhh5 | D3: concrete canoe | E3: Yellow - Stewardship concern (Address at next scheduled meeting) | F3: https://drive.google.com/open?id=1Cj39FQhlasJjzh3Sf41upPlEaOf7NAC0 | G3: Shared space (misuse of) | H3: Clear floor in storage area. | I3: Old | J3: =IFERROR(__xludf.DUMMYFUNCTION("IF(ISDATE(A3), DATE(YEAR(A3), MONTH(A3), DAY(A3)+ IFS(ISNUMBER(SEARCH(""Red"", E3)), 1, ISNUMBER(SEARCH(""Orange"", E3)), 3, ISNUMBER(SEARCH(""Yellow"", E3)), 10, ISNUMBER(SEARCH(""Ivory"", E3)), 21,TRUE, ""60"")), """")"),45928.0) -> 45928 | K3: 45931
A4: 45918.395 | B4: =CONCATENATE(C4,"@cornell.edu") -> Nhh5@cornell.edu | C4: Nhh5 | D4: Formula | E4: Yellow - Stewardship concern (Address at next scheduled meeting) | F4: https://drive.google.com/open?id=1Mc8D5g7mozMYaAZcBsNgDAp901dBI9qT | G4: Shared space (misuse of) | H4: Clear floor in storage area. | I4: Old | J4: =IFERROR(__xludf.DUMMYFUNCTION("IF(ISDATE(A4), DATE(YEAR(A4), MONTH(A4), DAY(A4)+ IFS(ISNUMBER(SEARCH(""Red"", E4)), 1, ISNUMBER(SEARCH(""Orange"", E4)), 3, ISNUMBER(SEARCH(""Yellow"", E4)), 10, ISNUMBER(SEARCH(""Ivory"", E4)), 21,TRUE, ""60"")), """")"),45928.0) -> 45928 | K4: 45931
A5: 45918.398 | B5: =CONCATENATE(C5,"@cornell.edu") -> Nhh5@cornell.edu | C5: Nhh5 | D5: concrete canoe | E5: Yellow - Stewardship concern (Address at next scheduled meeting) | F5: https://drive.google.com/open?id=1fUkZ-J4_Kys5RAB58s01JW6v30eo9AzT | G5: Housekeeping | H5: Empty trash barrels in HVL | I5: Email Sent | J5: =IFERROR(__xludf.DUMMYFUNCTION("IF(ISDATE(A5), DATE(YEAR(A5), MONTH(A5), DAY(A5)+ IFS(ISNUMBER(SEARCH(""Red"", E5)), 1, ISNUMBER(SEARCH(""Orange"", E5)), 3, ISNUMBER(SEARCH(""Yellow"", E5)), 10, ISNUMBER(SEARCH(""Ivory"", E5)), 21,TRUE, ""60"")), """")"),45928.0) -> 45928 | K5: 45931
A6: 45918.621 | B6: =CONCATENATE(C6,"@cornell.edu") -> Nhh5@cornell.edu | C6: Nhh5 | D6: Formula | E6: Orange - Operations/ Safety issue (resolve in 2-3 business days) | F6: https://drive.google.com/open?id=19rnv4vGnF9Xt7ZLx48vzx5YO834_awAw | G6: Shared space (misuse of) | H6: Move tables, coolers and canopy to penthouse | I6: Email Sent | J6: =IFERROR(__xludf.DUMMYFUNCTION("IF(ISDATE(A6), DATE(YEAR(A6), MONTH(A6), DAY(A6)+ IFS(ISNUMBER(SEARCH(""Red"", E6)), 1, ISNUMBER(SEARCH(""Orange"", E6)), 3, ISNUMBER(SEARCH(""Yellow"", E6)), 10, ISNUMBER(SEARCH(""Ivory"", E6)), 21,TRUE, ""60"")), """")"),45921.0) -> 45921 | K6: 45931
A7: 45919.718 | B7: =CONCATENATE(C7,"@cornell.edu") -> Nhh@cornell.edu | C7: Nhh | D7: concrete canoe | E7: Red - Code violation (immediate action Required) | F7: https://drive.google.com/open?id=1sVyU0mTazSzHvLjUdiOo4fX2uiTrtypC | G7: Fire / electrical (code violation) | H7: Move | I7: Email Sent | J7: =IFERROR(__xludf.DUMMYFUNCTION("IF(ISDATE(A7), DATE(YEAR(A7), MONTH(A7), DAY(A7)+ IFS(ISNUMBER(SEARCH(""Red"", E7)), 1, ISNUMBER(SEARCH(""Orange"", E7)), 3, ISNUMBER(SEARCH(""Yellow"", E7)), 10, ISNUMBER(SEARCH(""Ivory"", E7)), 21,TRUE, ""60"")), """")"),45920.0) -> 45920 | K7: 45931
A8: 45932.638 | B8: =CONCATENATE(C8,"@cornell.edu") -> Nhh5@cornell.edu | C8: Nhh5 | D8: Mars Rover | E8: Yellow - Stewardship concern (Address at next scheduled meeting) | F8: https://drive.google.com/open?id=15i9xzSWFPv9z9PeIcUNKH3ssC5nyvKvo | G8: Egress / access | H8: Move tool box from aisle | I8: Email Sent | J8: =IFERROR(__xludf.DUMMYFUNCTION("IF(ISDATE(A8), DATE(YEAR(A8), MONTH(A8), DAY(A8)+ IFS(ISNUMBER(SEARCH(""Red"", E8)), 1, ISNUMBER(SEARCH(""Orange"", E8)), 3, ISNUMBER(SEARCH(""Yellow"", E8)), 10, ISNUMBER(SEARCH(""Ivory"", E8)), 21,TRUE, ""60"")), """")"),45942.0) -> 45942 | K8: 45938
A9: 45932.695 | B9: =CONCATENATE(C9,"@cornell.edu") -> jam834@cornell.edu | C9: jam834 | D9: DEBUT | E9: Red - Code violation (immediate action Required) | F9: https://drive.google.com/open?id=1fxgTpXNCdpgbdzmNTtu4HbDfrWtOJMTn | G9: Fire / electrical (code violation) | H9: Move item away from electrical panel — area must be kept clear. | I9: Email Sent | J9: =IFERROR(__xludf.DUMMYFUNCTION("IF(ISDATE(A9), DATE(YEAR(A9), MONTH(A9), DAY(A9)+ IFS(ISNUMBER(SEARCH(""Red"", E9)), 1, ISNUMBER(SEARCH(""Orange"", E9)), 3, ISNUMBER(SEARCH(""Yellow"", E9)), 10, ISNUMBER(SEARCH(""Ivory"", E9)), 21,TRUE, ""60"")), """")"),45933.0) -> 45933 | K9: 45938
A10: 45933.384 | B10: =CONCATENATE(C10,"@cornell.edu") -> Nhh5@cornell.edu | C10: Nhh5 | D10: Operations Team | E10: Yellow - Stewardship concern (Address at next scheduled meeting) | F10: https://drive.google.com/open?id=1zTyHKHLN7vLoIi779WHc-U8YZIlEwKP4 | G10: Unsafe Work Practices | H10: Fix pedestal vise. | I10: Email Sent | J10: =IFERROR(__xludf.DUMMYFUNCTION("IF(ISDATE(A10), DATE(YEAR(A10), MONTH(A10), DAY(A10)+ IFS(ISNUMBER(SEARCH(""Red"", E10)), 1, ISNUMBER(SEARCH(""Orange"", E10)), 3, ISNUMBER(SEARCH(""Yellow"", E10)), 10, ISNUMBER(SEARCH(""Ivory"", E10)), 21,TRUE, ""60"")), """")"),45943.0) -> 45943 | K10: 45938
A11: 45933.396 | B11: =CONCATENATE(C11,"@cornell.edu") -> Nhh5 @cornell.edu | C11: Nhh5 | D11: Operations Team | E11: Ivory - Below standard (demonstrate improvement in 14-21 days) | F11: https://drive.google.com/open?id=13kUfFEkdHXepwkLwBTjrBuajGaT-xZnY | G11: Maintenance/ facilities | H11: Set up new vacuum pump. Move old smoky to HVL | I11: Email Sent | J11: =IFERROR(__xludf.DUMMYFUNCTION("IF(ISDATE(A11), DATE(YEAR(A11), MONTH(A11), DAY(A11)+ IFS(ISNUMBER(SEARCH(""Red"", E11)), 1, ISNUMBER(SEARCH(""Orange"", E11)), 3, ISNUMBER(SEARCH(""Yellow"", E11)), 10, ISNUMBER(SEARCH(""Ivory"", E11)), 21,TRUE, ""60"")), """")"),45954.0) -> 45954 | K11: 45938
A12: 45933.398 | B12: =CONCATENATE(C12,"@cornell.edu") -> Nhh5 @cornell.edu | C12: Nhh5 | D12: Operations Team | E12: Yellow - Stewardship concern (Address at next scheduled meeting) | F12: https://drive.google.com/open?id=16l_X5ZpmGtHh75Hv4Up14_pg8mO5oAUz | G12: Unsafe Work Practices | H12: Store respirators in appropriate containers | I12: Email Sent | J12: =IFERROR(__xludf.DUMMYFUNCTION("IF(ISDATE(A12), DATE(YEAR(A12), MONTH(A12), DAY(A12)+ IFS(ISNUMBER(SEARCH(""Red"", E12)), 1, ISNUMBER(SEARCH(""Orange"", E12)), 3, ISNUMBER(SEARCH(""Yellow"", E12)), 10, ISNUMBER(SEARCH(""Ivory"", E12)), 21,TRUE, ""60"")), """")"),45943.0) -> 45943 | K12: 45938
A13: 45933.399 | B13: =CONCATENATE(C13,"@cornell.edu") -> Nhh5 @cornell.edu | C13: Nhh5 | D13: Operations Team | E13: Yellow - Stewardship concern (Address at next scheduled meeting) | F13: https://drive.google.com/open?id=1dvJfl4IevUW-CeIfsjhePDQVPw3-OvXw | G13: Fire / electrical (code violation) | H13: Source replacement code compliant power supply | I13: Email Sent | J13: =IFERROR(__xludf.DUMMYFUNCTION("IF(ISDATE(A13), DATE(YEAR(A13), MONTH(A13), DAY(A13)+ IFS(ISNUMBER(SEARCH(""Red"", E13)), 1, ISNUMBER(SEARCH(""Orange"", E13)), 3, ISNUMBER(SEARCH(""Yellow"", E13)), 10, ISNUMBER(SEARCH(""Ivory"", E13)), 21,TRUE, ""60"")), """")"),45943.0) -> 45943 | K13: 45938
A14: 45933.403 | B14: =CONCATENATE(C14,"@cornell.edu") -> Nhh5 @cornell.edu | C14: Nhh5 | D14: Operations Team | E14: Purple - Opportunity for improvement (as time permits) | F14: https://drive.google.com/open?id=1de8HXNiKxiP1EIAvmTIH2ArUK5_RiVSZ | G14: Maintenance/ facilities | H14: Devise integrated storage mount for brushes and dust pans along with brooms. | I14: Email Sent | J14: =IFERROR(__xludf.DUMMYFUNCTION("IF(ISDATE(A14), DATE(YEAR(A14), MONTH(A14), DAY(A14)+ IFS(ISNUMBER(SEARCH(""Red"", E14)), 1, ISNUMBER(SEARCH(""Orange"", E14)), 3, ISNUMBER(SEARCH(""Yellow"", E14)), 10, ISNUMBER(SEARCH(""Ivory"", E14)), 21,TRUE, ""60"")), """")"),45993.0) -> 45993 | K14: 45938
A15: 45936.408 | B15: =CONCATENATE(C15,"@cornell.edu") -> Nhh5@cornell.edu | C15: Nhh5 | D15: Mars Rover | E15: Orange - Operations/ Safety issue (resolve in 2-3 business days) | F15: https://drive.google.com/open?id=1EigQr0yz4Nf_iDZNasaNwNT5iYrfuBjB | G15: Egress / access | H15: Remove carts from main hall | I15: Email Sent | J15: =IFERROR(__xludf.DUMMYFUNCTION("IF(ISDATE(A15), DATE(YEAR(A15), MONTH(A15), DAY(A15)+ IFS(ISNUMBER(SEARCH(""Red"", E15)), 1, ISNUMBER(SEARCH(""Orange"", E15)), 3, ISNUMBER(SEARCH(""Yellow"", E15)), 10, ISNUMBER(SEARCH(""Ivory"", E15)), 21,TRUE, ""60"")), """")"),45939.0) -> 45939 | K15: 45938
A16: 45937.522 | B16: =CONCATENATE(C16,"@cornell.edu") -> Nhh5@cornell.edu | C16: Nhh5 | D16: Operations Team | E16: Yellow - Stewardship concern (Address at next scheduled meeting) | F16: https://drive.google.com/open?id=1vneF2OPeq9ClRfKJh2-2CwxVGO2jfGyO | G16: Housekeeping | H16: Clear workbench. | I16: Email Sent | J16: =IFERROR(__xludf.DUMMYFUNCTION("IF(ISDATE(A16), DATE(YEAR(A16), MONTH(A16), DAY(A16)+ IFS(ISNUMBER(SEARCH(""Red"", E16)), 1, ISNUMBER(SEARCH(""Orange"", E16)), 3, ISNUMBER(SEARCH(""Yellow"", E16)), 10, ISNUMBER(SEARCH(""Ivory"", E16)), 21,TRUE, ""60"")), """")"),45947.0) -> 45947 | K16: 45938
A17: 45943.414 | B17: =CONCATENATE(C17,"@cornell.edu") -> Nhh5@cornell.edu | C17: Nhh5 | D17: Formula | E17: Yellow - Stewardship concern (Address at next scheduled meeting) | F17: https://drive.google.com/open?id=1ZjqE0xFBW0lrlbBGK6ncoZ3rXCgOPV5C | G17: Shared space (misuse of) | H17: Store material in cages or HVL racks | I17: Email Sent | J17: =IFERROR(__xludf.DUMMYFUNCTION("IF(ISDATE(A17), DATE(YEAR(A17), MONTH(A17), DAY(A17)+ IFS(ISNUMBER(SEARCH(""Red"", E17)), 1, ISNUMBER(SEARCH(""Orange"", E17)), 3, ISNUMBER(SEARCH(""Yellow"", E17)), 10, ISNUMBER(SEARCH(""Ivory"", E17)), 21,TRUE, ""60"")), """")"),45953.0) -> 45953 | K17: 45945
A18: 45943.416 | B18: =CONCATENATE(C18,"@cornell.edu") -> Nhh5@cornell.edu | C18: Nhh5 | D18: Baja | E18: Orange - Operations/ Safety issue (resolve in 2-3 business days) | F18: https://drive.google.com/open?id=1k8S-vzReA0gG3pY4Fibg1-_oiV_7KZVJ | G18: Fire / electrical (code violation) | H18: Learn access to panel and eye wash. | I18: Email Sent | J18: =IFERROR(__xludf.DUMMYFUNCTION("IF(ISDATE(A18), DATE(YEAR(A18), MONTH(A18), DAY(A18)+ IFS(ISNUMBER(SEARCH(""Red"", E18)), 1, ISNUMBER(SEARCH(""Orange"", E18)), 3, ISNUMBER(SEARCH(""Yellow"", E18)), 10, ISNUMBER(SEARCH(""Ivory"", E18)), 21,TRUE, ""60"")), """")"),45946.0) -> 45946 | K18: 45945
A19: 45946.681 | B19: =CONCATENATE(C19,"@cornell.edu") -> jam834@cornell.edu | C19: jam834 | D19: Operations Team | E19: Red - Code violation (same day action Required) | G19: Egress / access | H19: Engine crane, whiteboard, and chair cannot be left in front of electrical panel / yellow walkway. | I19: Email Sent | J19: =IFERROR(__xludf.DUMMYFUNCTION("IF(ISDATE(A19), DATE(YEAR(A19), MONTH(A19), DAY(A19)+ IFS(ISNUMBER(SEARCH(""Red"", E19)), 1, ISNUMBER(SEARCH(""Orange"", E19)), 3, ISNUMBER(SEARCH(""Yellow"", E19)), 10, ISNUMBER(SEARCH(""Ivory"", E19)), 21,TRUE, ""60"")), """")"),45947.0) -> 45947 | K19: 45947
A20: 45950.385 | B20: =CONCATENATE(C20,"@cornell.edu") -> nhh5@cornell.edu | C20: nhh5 | D20: Baja | E20: Red - Code violation (same day action Required) | F20: https://drive.google.com/open?id=18iOgpD_uJExXfOEng28xarrcXyN9R2xz | G20: Fire / electrical (code violation) | H20: Chain compressed gas cylinder to table leg | I20: Email Sent | J20: =IFERROR(__xludf.DUMMYFUNCTION("IF(ISDATE(A20), DATE(YEAR(A20), MONTH(A20), DAY(A20)+ IFS(ISNUMBER(SEARCH(""Red"", E20)), 1, ISNUMBER(SEARCH(""Orange"", E20)), 3, ISNUMBER(SEARCH(""Yellow"", E20)), 10, ISNUMBER(SEARCH(""Ivory"", E20)), 21,TRUE, ""60"")), """")"),45951.0) -> 45951 | K20: 45950
A21: 45952.584 | B21: =CONCATENATE(C21,"@cornell.edu") -> Nhh5@cornell.edu | C21: Nhh5 | D21: Operations Team | E21: Purple - Opportunity for improvement (as time permits) | F21: https://drive.google.com/open?id=1rD264d84PD7vjcoJN8BPcJsPtTNfB0WK | G21: Maintenance/ facilities | H21: Design better vertical storage for sheet goods. 4‘ x 8‘. | I21: Old | J21: =IFERROR(__xludf.DUMMYFUNCTION("IF(ISDATE(A21), DATE(YEAR(A21), MONTH(A21), DAY(A21)+ IFS(ISNUMBER(SEARCH(""Red"", E21)), 1, ISNUMBER(SEARCH(""Orange"", E21)), 3, ISNUMBER(SEARCH(""Yellow"", E21)), 10, ISNUMBER(SEARCH(""Ivory"", E21)), 21,TRUE, ""60"")), """")"),46012.0) -> 46012
A22: 45952.585 | B22: =CONCATENATE(C22,"@cornell.edu") -> Nhh5@cornell.edu | C22: Nhh5 | D22: Operations Team | E22: Ivory - Below standard (demonstrate improvement in 14-21 days) | F22: https://drive.google.com/open?id=1A97dmPWHNR31nQhwDIxersrMv-w3rTrW | G22: Maintenance/ facilities | H22: Replace paint booth exhaust filters | I22: Jatin and Eve took it on | J22: =IFERROR(__xludf.DUMMYFUNCTION("IF(ISDATE(A22), DATE(YEAR(A22), MONTH(A22), DAY(A22)+ IFS(ISNUMBER(SEARCH(""Red"", E22)), 1, ISNUMBER(SEARCH(""Orange"", E22)), 3, ISNUMBER(SEARCH(""Yellow"", E22)), 10, ISNUMBER(SEARCH(""Ivory"", E22)), 21,TRUE, ""60"")), """")"),45973.0) -> 45973 | K22: 45964
A23: 45959.376 | B23: =CONCATENATE(C23,"@cornell.edu") -> Nhh5@cornell.edu | C23: Nhh5 | D23: Baja | E23: Orange - Operations/ Safety issue (resolve in 2-3 business days) | G23: Unsafe Work Practices | H23: Get welder cables off floor. | I23: Email Sent | J23: =IFERROR(__xludf.DUMMYFUNCTION("IF(ISDATE(A23), DATE(YEAR(A23), MONTH(A23), DAY(A23)+ IFS(ISNUMBER(SEARCH(""Red"", E23)), 1, ISNUMBER(SEARCH(""Orange"", E23)), 3, ISNUMBER(SEARCH(""Yellow"", E23)), 10, ISNUMBER(SEARCH(""Ivory"", E23)), 21,TRUE, ""60"")), """")"),45962.0) -> 45962 | K23: 45962
A24: 45959.377 | B24: =CONCATENATE(C24,"@cornell.edu") -> Nhh5@cornell.edu | C24: Nhh5 | D24: Baja | E24: Red - Code violation (same day action Required) | F24: https://drive.google.com/open?id=1-7XqwdVL-j4aeqhs3MK4XY0jOus6LqOs | G24: Egress / access | H24: Clear access areas | I24: Email Sent | J24: =IFERROR(__xludf.DUMMYFUNCTION("IF(ISDATE(A24), DATE(YEAR(A24), MONTH(A24), DAY(A24)+ IFS(ISNUMBER(SEARCH(""Red"", E24)), 1, ISNUMBER(SEARCH(""Orange"", E24)), 3, ISNUMBER(SEARCH(""Yellow"", E24)), 10, ISNUMBER(SEARCH(""Ivory"", E24)), 21,TRUE, ""60"")), """")"),45960.0) -> 45960 | K24: 45960
A25: 45959.378 | B25: =CONCATENATE(C25,"@cornell.edu") -> Nhh5@cornell.edu | C25: Nhh5 | D25: Baja | E25: Red - Code violation (same day action Required) | F25: https://drive.google.com/open?id=1C2O9zg0kXZ8vKHEdR54vLTMAKOfPGGcS | G25: Fire / electrical (code violation) | H25: Store gas cans in flammables cabinet | I25: Email Sent | J25: =IFERROR(__xludf.DUMMYFUNCTION("IF(ISDATE(A25), DATE(YEAR(A25), MONTH(A25), DAY(A25)+ IFS(ISNUMBER(SEARCH(""Red"", E25)), 1, ISNUMBER(SEARCH(""Orange"", E25)), 3, ISNUMBER(SEARCH(""Yellow"", E25)), 10, ISNUMBER(SEARCH(""Ivory"", E25)), 21,TRUE, ""60"")), """")"),45960.0) -> 45960 | K25: 45960
A26: 45959.379 | B26: =CONCATENATE(C26,"@cornell.edu") -> Nhh5@cornell.edu | C26: Nhh5 | D26: Formula | E26: Red - Code violation (same day action Required) | F26: https://drive.google.com/open?id=1Djirgeu3f7r4fq4Xcew83PfEAO4Qsy5s | G26: Fire / electrical (code violation) | H26: Clear area in front of fire extinguisher | I26: Email Sent | J26: =IFERROR(__xludf.DUMMYFUNCTION("IF(ISDATE(A26), DATE(YEAR(A26), MONTH(A26), DAY(A26)+ IFS(ISNUMBER(SEARCH(""Red"", E26)), 1, ISNUMBER(SEARCH(""Orange"", E26)), 3, ISNUMBER(SEARCH(""Yellow"", E26)), 10, ISNUMBER(SEARCH(""Ivory"", E26)), 21,TRUE, ""60"")), """")"),45960.0) -> 45960 | K26: 45960
A27: 45959.675 | B27: =CONCATENATE(C27,"@cornell.edu") -> Nhh5@cornell.edu | C27: Nhh5 | D27: Operations Team | E27: Yellow - Stewardship concern (resolve in 7-10 days) | F27: https://drive.google.com/open?id=1TUZqpxJrsyJtnjf-jPi1ro9-BRdytLcd | G27: Egress / access | H27: Pick up stones from pavement and put them on island closer to the auto lab door so they don’t roll off again. | I27: Email Sent | J27: =IFERROR(__xludf.DUMMYFUNCTION("IF(ISDATE(A27), DATE(YEAR(A27), MONTH(A27), DAY(A27)+ IFS(ISNUMBER(SEARCH(""Red"", E27)), 1, ISNUMBER(SEARCH(""Orange"", E27)), 3, ISNUMBER(SEARCH(""Yellow"", E27)), 10, ISNUMBER(SEARCH(""Ivory"", E27)), 21,TRUE, ""60"")), """")"),45969.0) -> 45969 | K27: 45962
A28: 45961.384 | B28: =CONCATENATE(C28,"@cornell.edu") -> Nhh5@cornell.edu | C28: Nhh5 | D28: CUAir | E28: Yellow - Stewardship concern (resolve in 7-10 days) | G28: Shared space (misuse of) | H28: Store Orion parts in team space not in front of shared equipment. | I28: Email Sent | J28: =IFERROR(__xludf.DUMMYFUNCTION("IF(ISDATE(A28), DATE(YEAR(A28), MONTH(A28), DAY(A28)+ IFS(ISNUMBER(SEARCH(""Red"", E28)), 1, ISNUMBER(SEARCH(""Orange"", E28)), 3, ISNUMBER(SEARCH(""Yellow"", E28)), 10, ISNUMBER(SEARCH(""Ivory"", E28)), 21,TRUE, ""60"")), """")"),45971.0) -> 45971 | K28: 45972
A29: 45961.388 | B29: =CONCATENATE(C29,"@cornell.edu") -> Nhh5@cornell.edu | C29: Nhh5 | D29: Operations Team | E29: Orange - Operations/ Safety issue (resolve in 2-3 business days) | F29: https://drive.google.com/open?id=1rGDOeXchU_75BhP1HMOPWZ1q2L3BoXaP | G29: Unsafe Work Practices | H29: Secure lumber so it won’t fall and ID owners to advise same. | J29: =IFERROR(__xludf.DUMMYFUNCTION("IF(ISDATE(A29), DATE(YEAR(A29), MONTH(A29), DAY(A29)+ IFS(ISNUMBER(SEARCH(""Red"", E29)), 1, ISNUMBER(SEARCH(""Orange"", E29)), 3, ISNUMBER(SEARCH(""Yellow"", E29)), 10, ISNUMBER(SEARCH(""Ivory"", E29)), 21,TRUE, ""60"")), """")"),45964.0) -> 45964 | K29: 45965
A30: 45961.39 | B30: =CONCATENATE(C30,"@cornell.edu") -> Nhh5@cornell.edu | C30: Nhh5 | D30: Operations Team | E30: Yellow - Stewardship concern (resolve in 7-10 days) | F30: https://drive.google.com/open?id=1zYjmdJ0ZSWGRYxppxo0OuO_TA1SGLH5j | G30: Housekeeping | H30: Clear floor around workbench | J30: =IFERROR(__xludf.DUMMYFUNCTION("IF(ISDATE(A30), DATE(YEAR(A30), MONTH(A30), DAY(A30)+ IFS(ISNUMBER(SEARCH(""Red"", E30)), 1, ISNUMBER(SEARCH(""Orange"", E30)), 3, ISNUMBER(SEARCH(""Yellow"", E30)), 10, ISNUMBER(SEARCH(""Ivory"", E30)), 21,TRUE, ""60"")), """")"),45971.0) -> 45971 | K30: 45971
A31: 45961.394 | B31: =CONCATENATE(C31,"@cornell.edu") -> Nhh5@cornell.edu | C31: Nhh5 | D31: Baja | E31: Yellow - Stewardship concern (resolve in 7-10 days) | F31: https://drive.google.com/open?id=1D3qL8TNVc7-zvT5jNVjWzs4qgRazBxpV | G31: Housekeeping | H31: Please empty cabinet for relocation | I31: Email Sent | J31: =IFERROR(__xludf.DUMMYFUNCTION("IF(ISDATE(A31), DATE(YEAR(A31), MONTH(A31), DAY(A31)+ IFS(ISNUMBER(SEARCH(""Red"", E31)), 1, ISNUMBER(SEARCH(""Orange"", E31)), 3, ISNUMBER(SEARCH(""Yellow"", E31)), 10, ISNUMBER(SEARCH(""Ivory"", E31)), 21,TRUE, ""60"")), """")"),45971.0) -> 45971
A32: 45967.544 | B32: =CONCATENATE(C32,"@cornell.edu") -> Nhh5@cornell.edu | C32: Nhh5 | D32: Baja | E32: Purple - Opportunity for improvement (as time permits) | F32: https://drive.google.com/open?id=1o7d5biGDr7eD_qug17NvNQh1fYBUj_5q | G32: Unsafe Work Practices | H32: Test | I32: Email Sent | J32: =IFERROR(__xludf.DUMMYFUNCTION("IF(ISDATE(A32), DATE(YEAR(A32), MONTH(A32), DAY(A32)+ IFS(ISNUMBER(SEARCH(""Red"", E32)), 1, ISNUMBER(SEARCH(""Orange"", E32)), 3, ISNUMBER(SEARCH(""Yellow"", E32)), 10, ISNUMBER(SEARCH(""Ivory"", E32)), 21,TRUE, ""60"")), """")"),46027.0) -> 46027 | K32: 45966
A33: 45967.57 | B33: =CONCATENATE(C33,"@cornell.edu") -> Nhh5@cornell.edu | C33: Nhh5 | D33: CUAir | E33: Ivory - Below standard (demonstrate improvement in 14-21 days) | F33: https://drive.google.com/open?id=1yaJWGvoit8IELsPGJon8Uot_H55H-3Xt | G33: Housekeeping | H33: Clean up composites corner to improve access and organization | I33: Email Sent | J33: =IFERROR(__xludf.DUMMYFUNCTION("IF(ISDATE(A33), DATE(YEAR(A33), MONTH(A33), DAY(A33)+ IFS(ISNUMBER(SEARCH(""Red"", E33)), 1, ISNUMBER(SEARCH(""Orange"", E33)), 3, ISNUMBER(SEARCH(""Yellow"", E33)), 10, ISNUMBER(SEARCH(""Ivory"", E33)), 21,TRUE, ""60"")), """")"),45988.0) -> 45988
A34: 45967.572 | B34: =CONCATENATE(C34,"@cornell.edu") -> Nhh5 @cornell.edu | C34: Nhh5 | D34: CEV | E34: Yellow - Stewardship concern (resolve in 7-10 days) | F34: https://drive.google.com/open?id=1GU--yibtx14WJZ0_sNuqmbNL8j73iLRt | G34: Shared space (misuse of) | H34: Clear downdraft table when not in use | I34: Email Sent | J34: =IFERROR(__xludf.DUMMYFUNCTION("IF(ISDATE(A34), DATE(YEAR(A34), MONTH(A34), DAY(A34)+ IFS(ISNUMBER(SEARCH(""Red"", E34)), 1, ISNUMBER(SEARCH(""Orange"", E34)), 3, ISNUMBER(SEARCH(""Yellow"", E34)), 10, ISNUMBER(SEARCH(""Ivory"", E34)), 21,TRUE, ""60"")), """")"),45977.0) -> 45977 | K34: 45971
A35: 45971.375 | B35: nhh5@cornell.edu | C35: Nhh5 | D35: Formula | E35: Yellow - Stewardship Concern (resolve in 7-10 days) | F35: https://drive.google.com/open?id=1TsTIvzGNhcttVMZnPgTe3qVgU0VsCkeF | G35: Maintenance/ facilities | H35: Remove spray paint from wall outside autolab | I35: Email Sent | J35: =IFERROR(__xludf.DUMMYFUNCTION("IF(ISDATE(A35), DATE(YEAR(A35), MONTH(A35), DAY(A35)+ IFS(ISNUMBER(SEARCH(""Red"", E35)), 1, ISNUMBER(SEARCH(""Orange"", E35)), 3, ISNUMBER(SEARCH(""Yellow"", E35)), 10, ISNUMBER(SEARCH(""Ivory"", E35)), 21,TRUE, ""60"")), """")"),45981.0) -> 45981 | K35: 45972
A36: 45971.421 | B36: nhh5@cornell.edu | C36: Nhh5 | D36: Formula | E36: Yellow - Stewardship Concern (resolve in 7-10 days) | F36: https://drive.google.com/open?id=1iomJVuZ19QsXWRUe6B02t_ql9QHyqJTr | G36: Work Practices | H36: Please clear out painted rocks (put in dumpster) | I36: Email Sent | J36: =IFERROR(__xludf.DUMMYFUNCTION("IF(ISDATE(A36), DATE(YEAR(A36), MONTH(A36), DAY(A36)+ IFS(ISNUMBER(SEARCH(""Red"", E36)), 1, ISNUMBER(SEARCH(""Orange"", E36)), 3, ISNUMBER(SEARCH(""Yellow"", E36)), 10, ISNUMBER(SEARCH(""Ivory"", E36)), 21,TRUE, ""60"")), """")"),45981.0) -> 45981 | K36: 45972
A37: 45971.425 | B37: nhh5@cornell.edu | C37: Nhh5 | D37: Baja | E37: Orange - Operations Safety (resolve in 2-3 business days) | F37: https://drive.google.com/open?id=1l45SBxHjJXbdD2SEDfSi3sBh1qsgbE6r | G37: Chemical storage | H37: Empty oil into 5gal pail for R5 pickup. | I37: Email Sent | J37: =IFERROR(__xludf.DUMMYFUNCTION("IF(ISDATE(A37), DATE(YEAR(A37), MONTH(A37), DAY(A37)+ IFS(ISNUMBER(SEARCH(""Red"", E37)), 1, ISNUMBER(SEARCH(""Orange"", E37)), 3, ISNUMBER(SEARCH(""Yellow"", E37)), 10, ISNUMBER(SEARCH(""Ivory"", E37)), 21,TRUE, ""60"")), """")"),45974.0) -> 45974 | K37: 45973
A38: 45971.437 | B38: nhh5@cornell.edu | C38: Nhh5 | D38: Concrete Canoe | E38: Orange - Operations Safety (resolve in 2-3 business days) | F38: https://drive.google.com/open?id=1kFViKfhSK_t8CK6wcdJdNkaH7GrxyU95 | G38: Egress / access | H38: Assuming this is CCC’s - Move foam to HVL can’t block walkway. | I38: Email Sent | J38: =IFERROR(__xludf.DUMMYFUNCTION("IF(ISDATE(A38), DATE(YEAR(A38), MONTH(A38), DAY(A38)+ IFS(ISNUMBER(SEARCH(""Red"", E38)), 1, ISNUMBER(SEARCH(""Orange"", E38)), 3, ISNUMBER(SEARCH(""Yellow"", E38)), 10, ISNUMBER(SEARCH(""Ivory"", E38)), 21,TRUE, ""60"")), """")"),45974.0) -> 45974 | K38: 45978
A39: 45974.685 | B39: jam834@cornell.edu | C39: jam834 | D39: EWH | E39: Orange - Operations Safety (resolve in 2-3 business days) | F39: https://drive.google.com/open?id=16-2ZzgFD8n9wZYaniPOz0w6NisXEwoO_ | G39: Fire code | H39: Assuming EWH. Wheelchair cannot be in front of the electrical panel. A note has been left on the chair by myself and I moved the chair on one occasion, but it keeps being replaced there. | I39: Email Sent | J39: =IFERROR(__xludf.DUMMYFUNCTION("IF(ISDATE(A39), DATE(YEAR(A39), MONTH(A39), DAY(A39)+ IFS(ISNUMBER(SEARCH(""Red"", E39)), 1, ISNUMBER(SEARCH(""Orange"", E39)), 3, ISNUMBER(SEARCH(""Yellow"", E39)), 10, ISNUMBER(SEARCH(""Ivory"", E39)), 21,TRUE, ""60"")), """")"),45977.0) -> 45977
A40: 45974.686 | B40: jam834@cornell.edu | C40: jam834 | D40: EWH | E40: Orange - Operations Safety (resolve in 2-3 business days) | F40: https://drive.google.com/open?id=18GFZyZDJ1WJcR3ieXj1Yw5iJKXofAb_- | G40: Fire code | H40: Assuming EWH. Buckets / boxes cannot be placed in front of electrical panel. | I40: Email Sent | J40: =IFERROR(__xludf.DUMMYFUNCTION("IF(ISDATE(A40), DATE(YEAR(A40), MONTH(A40), DAY(A40)+ IFS(ISNUMBER(SEARCH(""Red"", E40)), 1, ISNUMBER(SEARCH(""Orange"", E40)), 3, ISNUMBER(SEARCH(""Yellow"", E40)), 10, ISNUMBER(SEARCH(""Ivory"", E40)), 21,TRUE, ""60"")), """")"),45977.0) -> 45977
...

Sheet Pending Actions
A1: Highlight of pending actions - Avoid duplication of status reports - do not edit.
A2: =IFERROR(__xludf.DUMMYFUNCTION("QUERY('Form Responses'!A1:X162, ""SELECT Col4, Col5, Col6, Col8, Col10 WHERE Col1 is not null AND Col11 is null AND NOT Col5 Contains 'Purple' AND NOT Col5 Contains 'Ivory' ORDER BY Col10 ASC LABEL Col4 'Team', Col6 'Photo'"")"),"Team") -> Team | B2: =IFERROR(__xludf.DUMMYFUNCTION("""COMPUTED_VALUE"""),"Current Status") -> Current Status | C2: =IFERROR(__xludf.DUMMYFUNCTION("""COMPUTED_VALUE"""),"Photo") -> Photo | D2: =IFERROR(__xludf.DUMMYFUNCTION("""COMPUTED_VALUE"""),"Required Actions / Comments") -> Required Actions / Comments | E2: =IFERROR(__xludf.DUMMYFUNCTION("""COMPUTED_VALUE"""),"Deadline") -> Deadline
A3: =IFERROR(__xludf.DUMMYFUNCTION("""COMPUTED_VALUE"""),"Baja") -> Baja | B3: =IFERROR(__xludf.DUMMYFUNCTION("""COMPUTED_VALUE"""),"Yellow - Stewardship concern (resolve in 7-10 days)") -> Yellow - Stewardship concern (resolve in 7-10 days) | C3: =IFERROR(__xludf.DUMMYFUNCTION("""COMPUTED_VALUE"""),"https://drive.google.com/open?id=1D3qL8TNVc7-zvT5jNVjWzs4qgRazBxpV") -> https://drive.google.com/open?id=1D3qL8TNVc7-zvT5jNVjWzs4qgRazBxpV | D3: =IFERROR(__xludf.DUMMYFUNCTION("""COMPUTED_VALUE"""),"Please empty cabinet for relocation ") -> Please empty cabinet for relocation | E3: =IFERROR(__xludf.DUMMYFUNCTION("""COMPUTED_VALUE"""),45971.0) -> 45971 | F3: FALSE
A4: =IFERROR(__xludf.DUMMYFUNCTION("""COMPUTED_VALUE"""),"EWH") -> EWH | B4: =IFERROR(__xludf.DUMMYFUNCTION("""COMPUTED_VALUE"""),"Orange - Operations Safety (resolve in 2-3 business days)") -> Orange - Operations Safety (resolve in 2-3 business days) | C4: =IFERROR(__xludf.DUMMYFUNCTION("""COMPUTED_VALUE"""),"https://drive.google.com/open?id=16-2ZzgFD8n9wZYaniPOz0w6NisXEwoO_") -> https://drive.google.com/open?id=16-2ZzgFD8n9wZYaniPOz0w6NisXEwoO_ | D4: =IFERROR(__xludf.DUMMYFUNCTION("""COMPUTED_VALUE"""),"Assuming EWH. Wheelchair cannot be in front of the electrical panel. A note has been left on the chair by myself and I moved the chair on one occasion, but it keeps being replaced there. ") -> Assuming EWH. Wheelchair cannot be in front of the electrical panel. A note has been left on the chair by myself and I moved the chair on one occasion, but it keeps being replaced there. | E4: =IFERROR(__xludf.DUMMYFUNCTION("""COMPUTED_VALUE"""),45977.0) -> 45977 | F4: FALSE
A5: =IFERROR(__xludf.DUMMYFUNCTION("""COMPUTED_VALUE"""),"EWH") -> EWH | B5: =IFERROR(__xludf.DUMMYFUNCTION("""COMPUTED_VALUE"""),"Orange - Operations Safety (resolve in 2-3 business days)") -> Orange - Operations Safety (resolve in 2-3 business days) | C5: =IFERROR(__xludf.DUMMYFUNCTION("""COMPUTED_VALUE"""),"https://drive.google.com/open?id=18GFZyZDJ1WJcR3ieXj1Yw5iJKXofAb_-") -> https://drive.google.com/open?id=18GFZyZDJ1WJcR3ieXj1Yw5iJKXofAb_- | D5: =IFERROR(__xludf.DUMMYFUNCTION("""COMPUTED_VALUE"""),"Assuming EWH. Buckets / boxes cannot be placed in front of electrical panel. ") -> Assuming EWH. Buckets / boxes cannot be placed in front of electrical panel. | E5: =IFERROR(__xludf.DUMMYFUNCTION("""COMPUTED_VALUE"""),45977.0) -> 45977 | F5: TRUE
A6: =IFERROR(__xludf.DUMMYFUNCTION("""COMPUTED_VALUE"""),"Unknown / unsure") -> Unknown / unsure | B6: =IFERROR(__xludf.DUMMYFUNCTION("""COMPUTED_VALUE"""),"Orange - Operations Safety (resolve in 2-3 business days)") -> Orange - Operations Safety (resolve in 2-3 business days) | C6: =IFERROR(__xludf.DUMMYFUNCTION("""COMPUTED_VALUE"""),"https://drive.google.com/open?id=1mQ8i67BWT-5bGibx-MAF1fsWzVJgi1QP") -> https://drive.google.com/open?id=1mQ8i67BWT-5bGibx-MAF1fsWzVJgi1QP | D6: =IFERROR(__xludf.DUMMYFUNCTION("""COMPUTED_VALUE"""),"None of the Baja / FSAE team members I've spoken to know whose this crane is, but it is blocking the walkway / electrical panel. I have moved it once before, but it continues to be placed in this spot. ") -> None of the Baja / FSAE team members I've spoken to know whose this crane is, but it is blocking the walkway / electrical panel. I have moved it once before, but it continues to be placed in this spot. | E6: =IFERROR(__xludf.DUMMYFUNCTION("""COMPUTED_VALUE"""),45977.0) -> 45977 | F6: FALSE
A7: =IFERROR(__xludf.DUMMYFUNCTION("""COMPUTED_VALUE"""),"Geodata") -> Geodata | B7: =IFERROR(__xludf.DUMMYFUNCTION("""COMPUTED_VALUE"""),"Yellow - Stewardship Concern (resolve in 7-10 days)") -> Yellow - Stewardship Concern (resolve in 7-10 days) | D7: =IFERROR(__xludf.DUMMYFUNCTION("""COMPUTED_VALUE"""),"Boxes appearing to contain geodata materials was placed in front of the EWH shelves. Please refrain from doing so and respect the storage areas of your fellow teams. The boxes were moved in front of the geodata shelves. ") -> Boxes appearing to contain geodata materials was placed in front of the EWH shelves. Please refrain from doing so and respect the storage areas of your fellow teams. The boxes were moved in front of the geodata shelves. | E7: =IFERROR(__xludf.DUMMYFUNCTION("""COMPUTED_VALUE"""),45986.0) -> 45986 | F7: TRUE
A8: =IFERROR(__xludf.DUMMYFUNCTION("""COMPUTED_VALUE"""),"Formula") -> Formula | B8: =IFERROR(__xludf.DUMMYFUNCTION("""COMPUTED_VALUE"""),"Yellow - Stewardship Concern (resolve in 7-10 days)") -> Yellow - Stewardship Concern (resolve in 7-10 days) | D8: =IFERROR(__xludf.DUMMYFUNCTION("""COMPUTED_VALUE"""),"Store material rolls so the won’t fall or lean on waste chemical drum") -> Store material rolls so the won’t fall or lean on waste chemical drum | E8: =IFERROR(__xludf.DUMMYFUNCTION("""COMPUTED_VALUE"""),45992.0) -> 45992 | F8: TRUE
A9: =IFERROR(__xludf.DUMMYFUNCTION("""COMPUTED_VALUE"""),"AutoBoat") -> AutoBoat | B9: =IFERROR(__xludf.DUMMYFUNCTION("""COMPUTED_VALUE"""),"Orange - Operations Safety (resolve in 2-3 business days)") -> Orange - Operations Safety (resolve in 2-3 business days) | C9: =IFERROR(__xludf.DUMMYFUNCTION("""COMPUTED_VALUE"""),"https://drive.google.com/open?id=123AIpsKqNibRFF3EB1mKLcqO3XH4F6Ds") -> https://drive.google.com/open?id=123AIpsKqNibRFF3EB1mKLcqO3XH4F6Ds | D9: =IFERROR(__xludf.DUMMYFUNCTION("""COMPUTED_VALUE"""),"Remove materials that are blocking access to flammables cabinets ") -> Remove materials that are blocking access to flammables cabinets | E9: =IFERROR(__xludf.DUMMYFUNCTION("""COMPUTED_VALUE"""),46046.0) -> 46046 | F9: TRUE
A10: =IFERROR(__xludf.DUMMYFUNCTION("""COMPUTED_VALUE"""),"Formula") -> Formula | B10: =IFERROR(__xludf.DUMMYFUNCTION("""COMPUTED_VALUE"""),"Orange - Operations Safety (resolve in 2-3 business days)") -> Orange - Operations Safety (resolve in 2-3 business days) | C10: =IFERROR(__xludf.DUMMYFUNCTION("""COMPUTED_VALUE"""),"https://drive.google.com/open?id=1H96S9ivvB4e3WGdp0t18sEs4wTBBL_di") -> https://drive.google.com/open?id=1H96S9ivvB4e3WGdp0t18sEs4wTBBL_di | D10: =IFERROR(__xludf.DUMMYFUNCTION("""COMPUTED_VALUE"""),"Move materials that are blocking access to flammables cabinets ") -> Move materials that are blocking access to flammables cabinets | E10: =IFERROR(__xludf.DUMMYFUNCTION("""COMPUTED_VALUE"""),46046.0) -> 46046 | F10: TRUE
A11: =IFERROR(__xludf.DUMMYFUNCTION("""COMPUTED_VALUE"""),"Baja") -> Baja | B11: =IFERROR(__xludf.DUMMYFUNCTION("""COMPUTED_VALUE"""),"Red - Code Compliance (same-day action Required)") -> Red - Code Compliance (same-day action Required) | C11: =IFERROR(__xludf.DUMMYFUNCTION("""COMPUTED_VALUE"""),"https://drive.google.com/open?id=1VXHv8A1J6d84DRsp3ztoxUEPNsEWvIUt") -> https://drive.google.com/open?id=1VXHv8A1J6d84DRsp3ztoxUEPNsEWvIUt | D11: =IFERROR(__xludf.DUMMYFUNCTION("""COMPUTED_VALUE"""),"Store fuel and flammables (not in hot work area), clear access areas for eye wash and electrical panel. ") -> Store fuel and flammables (not in hot work area), clear access areas for eye wash and electrical panel. | E11: =IFERROR(__xludf.DUMMYFUNCTION("""COMPUTED_VALUE"""),46052.0) -> 46052 | F11: TRUE
A12: =IFERROR(__xludf.DUMMYFUNCTION("""COMPUTED_VALUE"""),"Formula") -> Formula | B12: =IFERROR(__xludf.DUMMYFUNCTION("""COMPUTED_VALUE"""),"Red - Code Compliance (same-day action Required)") -> Red - Code Compliance (same-day action Required) | C12: =IFERROR(__xludf.DUMMYFUNCTION("""COMPUTED_VALUE"""),"https://drive.google.com/open?id=1ymY04ayEDichfhr93CXiBWvmyY-9MAy8") -> https://drive.google.com/open?id=1ymY04ayEDichfhr93CXiBWvmyY-9MAy8 | D12: =IFERROR(__xludf.DUMMYFUNCTION("""COMPUTED_VALUE"""),"Move field test extinguishers to storage") -> Move field test extinguishers to storage | E12: =IFERROR(__xludf.DUMMYFUNCTION("""COMPUTED_VALUE"""),46052.0) -> 46052 | F12: TRUE
A13: =IFERROR(__xludf.DUMMYFUNCTION("""COMPUTED_VALUE"""),"AutoBoat") -> AutoBoat | B13: =IFERROR(__xludf.DUMMYFUNCTION("""COMPUTED_VALUE"""),"Orange - Operations Safety (resolve in 2-3 business days)") -> Orange - Operations Safety (resolve in 2-3 business days) | C13: =IFERROR(__xludf.DUMMYFUNCTION("""COMPUTED_VALUE"""),"https://drive.google.com/open?id=1GeBWk2YHdB5lxc4Ks54YSWOsGuOgR29n") -> https://drive.google.com/open?id=1GeBWk2YHdB5lxc4Ks54YSWOsGuOgR29n | D13: =IFERROR(__xludf.DUMMYFUNCTION("""COMPUTED_VALUE"""),"Move materials that are blocking the equipment in the hallway. Can relocate to basement of rhodes hall (storage cages) rhodes penthouse storage cages, or the high volt lab. Consult with operations staff. ") -> Move materials that are blocking the equipment in the hallway. Can relocate to basement of rhodes hall (storage cages) rhodes penthouse storage cages, or the high volt lab. Consult with operations staff. | E13: =IFERROR(__xludf.DUMMYFUNCTION("""COMPUTED_VALUE"""),46054.0) -> 46054 | F13: FALSE
A14: =IFERROR(__xludf.DUMMYFUNCTION("""COMPUTED_VALUE"""),"Formula") -> Formula | B14: =IFERROR(__xludf.DUMMYFUNCTION("""COMPUTED_VALUE"""),"Orange - Operations Safety (resolve in 2-3 business days)") -> Orange - Operations Safety (resolve in 2-3 business days) | C14: =IFERROR(__xludf.DUMMYFUNCTION("""COMPUTED_VALUE"""),"https://drive.google.com/open?id=1-5zH3kfAOTfFAemrPT6JUNMwQC2geGTL") -> https://drive.google.com/open?id=1-5zH3kfAOTfFAemrPT6JUNMwQC2geGTL | D14: =IFERROR(__xludf.DUMMYFUNCTION("""COMPUTED_VALUE"""),"Reroute cables to eliminate tripping hazard") -> Reroute cables to eliminate tripping hazard | E14: =IFERROR(__xludf.DUMMYFUNCTION("""COMPUTED_VALUE"""),46054.0) -> 46054 | F14: FALSE
A15: =IFERROR(__xludf.DUMMYFUNCTION("""COMPUTED_VALUE"""),"CUBMD") -> CUBMD | B15: =IFERROR(__xludf.DUMMYFUNCTION("""COMPUTED_VALUE"""),"Yellow - Stewardship Concern (resolve in 7-10 days)") -> Yellow - Stewardship Concern (resolve in 7-10 days) | C15: =IFERROR(__xludf.DUMMYFUNCTION("""COMPUTED_VALUE"""),"https://drive.google.com/open?id=1gwY0e1fP97A6wn3fchNxHbcOBaLPp_qo") -> https://drive.google.com/open?id=1gwY0e1fP97A6wn3fchNxHbcOBaLPp_qo | D15: =IFERROR(__xludf.DUMMYFUNCTION("""COMPUTED_VALUE"""),"Clear team stuff from reservable table when not in use. ") -> Clear team stuff from reservable table when not in use. | E15: =IFERROR(__xludf.DUMMYFUNCTION("""COMPUTED_VALUE"""),46055.0) -> 46055 | F15: FALSE
A16: =IFERROR(__xludf.DUMMYFUNCTION("""COMPUTED_VALUE"""),"EWB") -> EWB | B16: =IFERROR(__xludf.DUMMYFUNCTION("""COMPUTED_VALUE"""),"Yellow - Stewardship Concern (resolve in 7-10 days)") -> Yellow - Stewardship Concern (resolve in 7-10 days) | C16: =IFERROR(__xludf.DUMMYFUNCTION("""COMPUTED_VALUE"""),"https://drive.google.com/open?id=1FYy9H_zLArSs6XnS0tonCP7EtnjkWSjm") -> https://drive.google.com/open?id=1FYy9H_zLArSs6XnS0tonCP7EtnjkWSjm | D16: =IFERROR(__xludf.DUMMYFUNCTION("""COMPUTED_VALUE"""),"Remove teams things from miserable table when not in use") -> Remove teams things from miserable table when not in use | E16: =IFERROR(__xludf.DUMMYFUNCTION("""COMPUTED_VALUE"""),46055.0) -> 46055 | F16: FALSE
A17: =IFERROR(__xludf.DUMMYFUNCTION("""COMPUTED_VALUE"""),"ESW") -> ESW | B17: =IFERROR(__xludf.DUMMYFUNCTION("""COMPUTED_VALUE"""),"Yellow - Stewardship Concern (resolve in 7-10 days)") -> Yellow - Stewardship Concern (resolve in 7-10 days) | C17: =IFERROR(__xludf.DUMMYFUNCTION("""COMPUTED_VALUE"""),"https://drive.google.com/open?id=1n9E8iMrdcuLE-S7YWD0QFdQPTbw_ASXM") -> https://drive.google.com/open?id=1n9E8iMrdcuLE-S7YWD0QFdQPTbw_ASXM | D17: =IFERROR(__xludf.DUMMYFUNCTION("""COMPUTED_VALUE"""),"Remove team’s things from reservable table when not in use") -> Remove team’s things from reservable table when not in use | E17: =IFERROR(__xludf.DUMMYFUNCTION("""COMPUTED_VALUE"""),46055.0) -> 46055 | F17: FALSE
A18: =IFERROR(__xludf.DUMMYFUNCTION("""COMPUTED_VALUE"""),"Steel Bridge") -> Steel Bridge | B18: =IFERROR(__xludf.DUMMYFUNCTION("""COMPUTED_VALUE"""),"Yellow - Stewardship Concern (resolve in 7-10 days)") -> Yellow - Stewardship Concern (resolve in 7-10 days) | C18: =IFERROR(__xludf.DUMMYFUNCTION("""COMPUTED_VALUE"""),"https://drive.google.com/open?id=1IiOsx9cC44RRxC1rZpDA9S1cAXw0-1dV") -> https://drive.google.com/open?id=1IiOsx9cC44RRxC1rZpDA9S1cAXw0-1dV | D18: =IFERROR(__xludf.DUMMYFUNCTION("""COMPUTED_VALUE"""),"Please move as much of the metal stock as possible onto the lowest storage shelf and consolidate the rest to clear the walkway. ") -> Please move as much of the metal stock as possible onto the lowest storage shelf and consolidate the rest to clear the walkway. | E18: =IFERROR(__xludf.DUMMYFUNCTION("""COMPUTED_VALUE"""),46059.0) -> 46059 | F18: FALSE
A19: =IFERROR(__xludf.DUMMYFUNCTION("""COMPUTED_VALUE"""),"DEBUT") -> DEBUT | B19: =IFERROR(__xludf.DUMMYFUNCTION("""COMPUTED_VALUE"""),"Orange - Operations Safety (resolve in 2-3 business days)") -> Orange - Operations Safety (resolve in 2-3 business days) | C19: =IFERROR(__xludf.DUMMYFUNCTION("""COMPUTED_VALUE"""),"https://drive.google.com/open?id=1iOJWkEejMvijXob_rhDXUeHslAd4laYN") -> https://drive.google.com/open?id=1iOJWkEejMvijXob_rhDXUeHslAd4laYN | D19: =IFERROR(__xludf.DUMMYFUNCTION("""COMPUTED_VALUE"""),"Wheelchair cannot be blocking the electrical panel. Chair moved out of the way.") -> Wheelchair cannot be blocking the electrical panel. Chair moved out of the way. | E19: =IFERROR(__xludf.DUMMYFUNCTION("""COMPUTED_VALUE"""),46059.0) -> 46059 | F19: TRUE
A20: =IFERROR(__xludf.DUMMYFUNCTION("""COMPUTED_VALUE"""),"Formula") -> Formula | B20: =IFERROR(__xludf.DUMMYFUNCTION("""COMPUTED_VALUE"""),"Yellow - Stewardship Concern (resolve in 7-10 days)") -> Yellow - Stewardship Concern (resolve in 7-10 days) | C20: =IFERROR(__xludf.DUMMYFUNCTION("""COMPUTED_VALUE"""),"https://drive.google.com/open?id=1Sxgx7LoZNK5bS7JrQSzKlFpmebduI5MZ") -> https://drive.google.com/open?id=1Sxgx7LoZNK5bS7JrQSzKlFpmebduI5MZ | D20: =IFERROR(__xludf.DUMMYFUNCTION("""COMPUTED_VALUE"""),"Move materials to storage. ") -> Move materials to storage. | E20: =IFERROR(__xludf.DUMMYFUNCTION("""COMPUTED_VALUE"""),46061.0) -> 46061 | F20: FALSE
A21: =IFERROR(__xludf.DUMMYFUNCTION("""COMPUTED_VALUE"""),"Baja") -> Baja | B21: =IFERROR(__xludf.DUMMYFUNCTION("""COMPUTED_VALUE"""),"Yellow - Stewardship Concern (resolve in 7-10 days)") -> Yellow - Stewardship Concern (resolve in 7-10 days) | C21: =IFERROR(__xludf.DUMMYFUNCTION("""COMPUTED_VALUE"""),"https://drive.google.com/open?id=1dZBknIO9wAfF2yogyx4h_it3hjqU7Hb6") -> https://drive.google.com/open?id=1dZBknIO9wAfF2yogyx4h_it3hjqU7Hb6 | D21: =IFERROR(__xludf.DUMMYFUNCTION("""COMPUTED_VALUE"""),"Move materials to storage. ") -> Move materials to storage. | E21: =IFERROR(__xludf.DUMMYFUNCTION("""COMPUTED_VALUE"""),46061.0) -> 46061 | F21: FALSE
A22: =IFERROR(__xludf.DUMMYFUNCTION("""COMPUTED_VALUE"""),"CUAir") -> CUAir | B22: =IFERROR(__xludf.DUMMYFUNCTION("""COMPUTED_VALUE"""),"Yellow - Stewardship Concern (resolve in 7-10 days)") -> Yellow - Stewardship Concern (resolve in 7-10 days) | C22: =IFERROR(__xludf.DUMMYFUNCTION("""COMPUTED_VALUE"""),"https://drive.google.com/open?id=1Eur9CX_es2zhaRGL9CkYPvSJQryCmXBO") -> https://drive.google.com/open?id=1Eur9CX_es2zhaRGL9CkYPvSJQryCmXBO | D22: =IFERROR(__xludf.DUMMYFUNCTION("""COMPUTED_VALUE"""),"Tidy up area, store chemicals and remove excess cardboard from upper shelving. ") -> Tidy up area, store chemicals and remove excess cardboard from upper shelving. | E22: =IFERROR(__xludf.DUMMYFUNCTION("""COMPUTED_VALUE"""),46061.0) -> 46061 | F22: FALSE
A23: =IFERROR(__xludf.DUMMYFUNCTION("""COMPUTED_VALUE"""),"Formula") -> Formula | B23: =IFERROR(__xludf.DUMMYFUNCTION("""COMPUTED_VALUE"""),"Yellow - Stewardship Concern (resolve in 7-10 days)") -> Yellow - Stewardship Concern (resolve in 7-10 days) | C23: =IFERROR(__xludf.DUMMYFUNCTION("""COMPUTED_VALUE"""),"https://drive.google.com/open?id=1piiK5nWmTlQO2SDuG9uLGfZcZ3IfgQIm") -> https://drive.google.com/open?id=1piiK5nWmTlQO2SDuG9uLGfZcZ3IfgQIm | D23: =IFERROR(__xludf.DUMMYFUNCTION("""COMPUTED_VALUE"""),"Tidy up hallway and toss recycling. ") -> Tidy up hallway and toss recycling. | E23: =IFERROR(__xludf.DUMMYFUNCTION("""COMPUTED_VALUE"""),46061.0) -> 46061 | F23: FALSE
A24: =IFERROR(__xludf.DUMMYFUNCTION("""COMPUTED_VALUE"""),"Formula") -> Formula | B24: =IFERROR(__xludf.DUMMYFUNCTION("""COMPUTED_VALUE"""),"Yellow - Stewardship Concern (resolve in 7-10 days)") -> Yellow - Stewardship Concern (resolve in 7-10 days) | C24: =IFERROR(__xludf.DUMMYFUNCTION("""COMPUTED_VALUE"""),"https://drive.google.com/open?id=1pMGblt_xj3L9UkKzdDwZa2Jzxiq5mozv") -> https://drive.google.com/open?id=1pMGblt_xj3L9UkKzdDwZa2Jzxiq5mozv | D24: =IFERROR(__xludf.DUMMYFUNCTION("""COMPUTED_VALUE"""),"Remove plywood from b60") -> Remove plywood from b60 | E24: =IFERROR(__xludf.DUMMYFUNCTION("""COMPUTED_VALUE"""),46061.0) -> 46061 | F24: FALSE
A25: =IFERROR(__xludf.DUMMYFUNCTION("""COMPUTED_VALUE"""),"Unknown / unsure") -> Unknown / unsure | B25: =IFERROR(__xludf.DUMMYFUNCTION("""COMPUTED_VALUE"""),"Orange - Operations Safety (resolve in 2-3 business days)") -> Orange - Operations Safety (resolve in 2-3 business days) | C25: =IFERROR(__xludf.DUMMYFUNCTION("""COMPUTED_VALUE"""),"https://drive.google.com/open?id=12B-9rB2hdSCYwngV6_Ps2_-tBwbC_xsY") -> https://drive.google.com/open?id=12B-9rB2hdSCYwngV6_Ps2_-tBwbC_xsY | D25: =IFERROR(__xludf.DUMMYFUNCTION("""COMPUTED_VALUE"""),"Materials in fire lane, unsure of whose") -> Materials in fire lane, unsure of whose | E25: =IFERROR(__xludf.DUMMYFUNCTION("""COMPUTED_VALUE"""),46068.0) -> 46068 | F25: FALSE
A26: =IFERROR(__xludf.DUMMYFUNCTION("""COMPUTED_VALUE"""),"Baja") -> Baja | B26: =IFERROR(__xludf.DUMMYFUNCTION("""COMPUTED_VALUE"""),"Red - Code Compliance (same-day action Required)") -> Red - Code Compliance (same-day action Required) | C26: =IFERROR(__xludf.DUMMYFUNCTION("""COMPUTED_VALUE"""),"https://drive.google.com/open?id=1ki7v4nFCI88KEppqhRE-QyFNxWm_YwEM") -> https://drive.google.com/open?id=1ki7v4nFCI88KEppqhRE-QyFNxWm_YwEM | D26: =IFERROR(__xludf.DUMMYFUNCTION("""COMPUTED_VALUE"""),"Clear panel access areas") -> Clear panel access areas | E26: =IFERROR(__xludf.DUMMYFUNCTION("""COMPUTED_VALUE"""),46078.0) -> 46078 | F26: FALSE
A27: =IFERROR(__xludf.DUMMYFUNCTION("""COMPUTED_VALUE"""),"Formula") -> Formula | B27: =IFERROR(__xludf.DUMMYFUNCTION("""COMPUTED_VALUE"""),"Red - Code Compliance (same-day action Required)") -> Red - Code Compliance (same-day action Required) | C27: =IFERROR(__xludf.DUMMYFUNCTION("""COMPUTED_VALUE"""),"https://drive.google.com/open?id=1nR7RLvHjbAS8MFvnLgpx2j1aRMe4P812") -> https://drive.google.com/open?id=1nR7RLvHjbAS8MFvnLgpx2j1aRMe4P812 | D27: =IFERROR(__xludf.DUMMYFUNCTION("""COMPUTED_VALUE"""),"Move cones to avoid blocking extinguisher") -> Move cones to avoid blocking extinguisher | E27: =IFERROR(__xludf.DUMMYFUNCTION("""COMPUTED_VALUE"""),46078.0) -> 46078 | F27: FALSE
A28: =IFERROR(__xludf.DUMMYFUNCTION("""COMPUTED_VALUE"""),"Formula") -> Formula | B28: =IFERROR(__xludf.DUMMYFUNCTION("""COMPUTED_VALUE"""),"Red - Code Compliance (same-day action Required)") -> Red - Code Compliance (same-day action Required) | C28: =IFERROR(__xludf.DUMMYFUNCTION("""COMPUTED_VALUE"""),"https://drive.google.com/open?id=11PKC4BzJgcJ6OxM43nSFywrXKQV-qj4Z") -> https://drive.google.com/open?id=11PKC4BzJgcJ6OxM43nSFywrXKQV-qj4Z | D28: =IFERROR(__xludf.DUMMYFUNCTION("""COMPUTED_VALUE"""),"Move materials to Rhodes basement cages or HVL to clear hallway ") -> Move materials to Rhodes basement cages or HVL to clear hallway | E28: =IFERROR(__xludf.DUMMYFUNCTION("""COMPUTED_VALUE"""),46078.0) -> 46078 | F28: FALSE
A29: =IFERROR(__xludf.DUMMYFUNCTION("""COMPUTED_VALUE"""),"Baja") -> Baja | B29: =IFERROR(__xludf.DUMMYFUNCTION("""COMPUTED_VALUE"""),"Red - Code Compliance (same-day action Required)") -> Red - Code Compliance (same-day action Required) | C29: =IFERROR(__xludf.DUMMYFUNCTION("""COMPUTED_VALUE"""),"https://drive.google.com/open?id=1ryDai6C-m7tpWQipCHZinxgjT5EwpJ3w") -> https://drive.google.com/open?id=1ryDai6C-m7tpWQipCHZinxgjT5EwpJ3w | D29: =IFERROR(__xludf.DUMMYFUNCTION("""COMPUTED_VALUE"""),"Move materials to Rhodes storage or HVL to clear hallway") -> Move materials to Rhodes storage or HVL to clear hallway | E29: =IFERROR(__xludf.DUMMYFUNCTION("""COMPUTED_VALUE"""),46078.0) -> 46078 | F29: FALSE
A30: =IFERROR(__xludf.DUMMYFUNCTION("""COMPUTED_VALUE"""),"CEV") -> CEV | B30: =IFERROR(__xludf.DUMMYFUNCTION("""COMPUTED_VALUE"""),"Red - Code Compliance (same-day action Required)") -> Red - Code Compliance (same-day action Required) | C30: =IFERROR(__xludf.DUMMYFUNCTION("""COMPUTED_VALUE"""),"https://drive.google.com/open?id=1to3zKfiqP5pSmoXTjMb11puq3qxbQUhk") -> https://drive.google.com/open?id=1to3zKfiqP5pSmoXTjMb11puq3qxbQUhk | D30: =IFERROR(__xludf.DUMMYFUNCTION("""COMPUTED_VALUE"""),"Clean up and organize composites space. Remove combustibles. Use Rhodes basement cages or HVL for storage if necessary ") -> Clean up and organize composites space. Remove combustibles. Use Rhodes basement cages or HVL for storage if necessary | E30: =IFERROR(__xludf.DUMMYFUNCTION("""COMPUTED_VALUE"""),46078.0) -> 46078 | F30: FALSE
A31: =IFERROR(__xludf.DUMMYFUNCTION("""COMPUTED_VALUE"""),"Formula") -> Formula | B31: =IFERROR(__xludf.DUMMYFUNCTION("""COMPUTED_VALUE"""),"Red - Code Compliance (same-day action Required)") -> Red - Code Compliance (same-day action Required) | C31: =IFERROR(__xludf.DUMMYFUNCTION("""COMPUTED_VALUE"""),"https://drive.google.com/open?id=1RWYNAcqHGg2S5swtIQFLLkbkRavyk9i_") -> https://drive.google.com/open?id=1RWYNAcqHGg2S5swtIQFLLkbkRavyk9i_ | D31: =IFERROR(__xludf.DUMMYFUNCTION("""COMPUTED_VALUE"""),"Remove/ store material rolls ") -> Remove/ store material rolls | E31: =IFERROR(__xludf.DUMMYFUNCTION("""COMPUTED_VALUE"""),46078.0) -> 46078 | F31: FALSE
A32: =IFERROR(__xludf.DUMMYFUNCTION("""COMPUTED_VALUE"""),"Formula") -> Formula | B32: =IFERROR(__xludf.DUMMYFUNCTION("""COMPUTED_VALUE"""),"Red - Code Compliance (same-day action Required)") -> Red - Code Compliance (same-day action Required) | C32: =IFERROR(__xludf.DUMMYFUNCTION("""COMPUTED_VALUE"""),"https://drive.google.com/open?id=18aDWjAopFZClybVzoy9VYApFcTkAnhEr") -> https://drive.google.com/open?id=18aDWjAopFZClybVzoy9VYApFcTkAnhEr | D32: =IFERROR(__xludf.DUMMYFUNCTION("""COMPUTED_VALUE"""),"Clear floor as much as possible ") -> Clear floor as much as possible | E32: =IFERROR(__xludf.DUMMYFUNCTION("""COMPUTED_VALUE"""),46078.0) -> 46078
A33: =IFERROR(__xludf.DUMMYFUNCTION("""COMPUTED_VALUE"""),"Design Build Fly") -> Design Build Fly | B33: =IFERROR(__xludf.DUMMYFUNCTION("""COMPUTED_VALUE"""),"Red - Code Compliance (same-day action Required)") -> Red - Code Compliance (same-day action Required) | C33: =IFERROR(__xludf.DUMMYFUNCTION("""COMPUTED_VALUE"""),"https://drive.google.com/open?id=1aLQZOt63rSPcMQdCmvzQe66XrebwpcgM") -> https://drive.google.com/open?id=1aLQZOt63rSPcMQdCmvzQe66XrebwpcgM | D33: =IFERROR(__xludf.DUMMYFUNCTION("""COMPUTED_VALUE"""),"Generator must be empty of fuel or moved to HVL or Rhodes penthouse") -> Generator must be empty of fuel or moved to HVL or Rhodes penthouse | E33: =IFERROR(__xludf.DUMMYFUNCTION("""COMPUTED_VALUE"""),46078.0) -> 46078
A34: =IFERROR(__xludf.DUMMYFUNCTION("""COMPUTED_VALUE"""),"Concrete Canoe") -> Concrete Canoe | B34: =IFERROR(__xludf.DUMMYFUNCTION("""COMPUTED_VALUE"""),"Orange - Operations Safety (resolve in 2-3 business days)") -> Orange - Operations Safety (resolve in 2-3 business days) | C34: =IFERROR(__xludf.DUMMYFUNCTION("""COMPUTED_VALUE"""),"https://drive.google.com/open?id=1G2Hax0RSCyVwEUURElK7o2C9EIR9KdDk") -> https://drive.google.com/open?id=1G2Hax0RSCyVwEUURElK7o2C9EIR9KdDk | D34: =IFERROR(__xludf.DUMMYFUNCTION("""COMPUTED_VALUE"""),"Please pick up these new vacuums and dust control lids for the mix crew and bring them to the HVL ASAP") -> Please pick up these new vacuums and dust control lids for the mix crew and bring them to the HVL ASAP | E34: =IFERROR(__xludf.DUMMYFUNCTION("""COMPUTED_VALUE"""),46079.0) -> 46079
A35: =IFERROR(__xludf.DUMMYFUNCTION("""COMPUTED_VALUE"""),"CEV") -> CEV | B35: =IFERROR(__xludf.DUMMYFUNCTION("""COMPUTED_VALUE"""),"Orange - Operations Safety (resolve in 2-3 business days)") -> Orange - Operations Safety (resolve in 2-3 business days) | C35: =IFERROR(__xludf.DUMMYFUNCTION("""COMPUTED_VALUE"""),"https://drive.google.com/open?id=1dsW-H0n7DZvHBvsi6AOY_4LsJpGdsyRj") -> https://drive.google.com/open?id=1dsW-H0n7DZvHBvsi6AOY_4LsJpGdsyRj | D35: =IFERROR(__xludf.DUMMYFUNCTION("""COMPUTED_VALUE"""),"Need to clean up CEV space in composites lab by end of day Wednesday for fire inspection. ") -> Need to clean up CEV space in composites lab by end of day Wednesday for fire inspection. | E35: =IFERROR(__xludf.DUMMYFUNCTION("""COMPUTED_VALUE"""),46079.0) -> 46079
A36: =IFERROR(__xludf.DUMMYFUNCTION("""COMPUTED_VALUE"""),"Rocketry") -> Rocketry | B36: =IFERROR(__xludf.DUMMYFUNCTION("""COMPUTED_VALUE"""),"Red - Code Compliance (same-day action Required)") -> Red - Code Compliance (same-day action Required) | D36: =IFERROR(__xludf.DUMMYFUNCTION("""COMPUTED_VALUE"""),"Please remove propane tank from inside HVL before 2pm today if at all possible. You can leave it in the back of the project truck if you need to. ") -> Please remove propane tank from inside HVL before 2pm today if at all possible. You can leave it in the back of the project truck if you need to. | E36: =IFERROR(__xludf.DUMMYFUNCTION("""COMPUTED_VALUE"""),46080.0) -> 46080
A37: =IFERROR(__xludf.DUMMYFUNCTION("""COMPUTED_VALUE"""),"Rocketry") -> Rocketry | B37: =IFERROR(__xludf.DUMMYFUNCTION("""COMPUTED_VALUE"""),"Orange - Operations Safety (resolve in 2-3 business days)") -> Orange - Operations Safety (resolve in 2-3 business days) | C37: =IFERROR(__xludf.DUMMYFUNCTION("""COMPUTED_VALUE"""),"https://drive.google.com/open?id=1v_wL6ihOmYNmNpa0LP4SyI2JM7SoGNYP") -> https://drive.google.com/open?id=1v_wL6ihOmYNmNpa0LP4SyI2JM7SoGNYP | D37: =IFERROR(__xludf.DUMMYFUNCTION("""COMPUTED_VALUE"""),"Empty and return recycling container") -> Empty and return recycling container | E37: =IFERROR(__xludf.DUMMYFUNCTION("""COMPUTED_VALUE"""),46083.0) -> 46083
A38: =IFERROR(__xludf.DUMMYFUNCTION("""COMPUTED_VALUE"""),"Unknown / unsure") -> Unknown / unsure | B38: =IFERROR(__xludf.DUMMYFUNCTION("""COMPUTED_VALUE"""),"Yellow - Stewardship Concern (resolve in 7-10 days)") -> Yellow - Stewardship Concern (resolve in 7-10 days) | C38: =IFERROR(__xludf.DUMMYFUNCTION("""COMPUTED_VALUE"""),"https://drive.google.com/open?id=1dAHvHu_sGzkcmCqsU--UuFco0dnsz7DR") -> https://drive.google.com/open?id=1dAHvHu_sGzkcmCqsU--UuFco0dnsz7DR | D38: =IFERROR(__xludf.DUMMYFUNCTION("""COMPUTED_VALUE"""),"Consolidate work area and clear aisle") -> Consolidate work area and clear aisle | E38: =IFERROR(__xludf.DUMMYFUNCTION("""COMPUTED_VALUE"""),46087.0) -> 46087
A39: =IFERROR(__xludf.DUMMYFUNCTION("""COMPUTED_VALUE"""),"Baja") -> Baja | B39: =IFERROR(__xludf.DUMMYFUNCTION("""COMPUTED_VALUE"""),"Yellow - Stewardship Concern (resolve in 7-10 days)") -> Yellow - Stewardship Concern (resolve in 7-10 days) | C39: =IFERROR(__xludf.DUMMYFUNCTION("""COMPUTED_VALUE"""),"https://drive.google.com/open?id=1ocbQXMShsQdXb2SaCoh1_dJXSU7IB2xF") -> https://drive.google.com/open?id=1ocbQXMShsQdXb2SaCoh1_dJXSU7IB2xF | D39: =IFERROR(__xludf.DUMMYFUNCTION("""COMPUTED_VALUE"""),"Move cars onto Cornell property near HVL. ") -> Move cars onto Cornell property near HVL. | E39: =IFERROR(__xludf.DUMMYFUNCTION("""COMPUTED_VALUE"""),46102.0) -> 46102
A40: =IFERROR(__xludf.DUMMYFUNCTION("""COMPUTED_VALUE"""),"CU Sail") -> CU Sail | B40: =IFERROR(__xludf.DUMMYFUNCTION("""COMPUTED_VALUE"""),"Yellow - Stewardship Concern (resolve in 7-10 days)") -> Yellow - Stewardship Concern (resolve in 7-10 days) | C40: =IFERROR(__xludf.DUMMYFUNCTION("""COMPUTED_VALUE"""),"https://drive.google.com/open?id=1gsRIqZ-1kiVnHYbPxfT1nURl-tigpH5i") -> https://drive.google.com/open?id=1gsRIqZ-1kiVnHYbPxfT1nURl-tigpH5i | D40: =IFERROR(__xludf.DUMMYFUNCTION("""COMPUTED_VALUE"""),"Do not put hardening chemicals in paint funnel") -> Do not put hardening chemicals in paint funnel | E40: =IFERROR(__xludf.DUMMYFUNCTION("""COMPUTED_VALUE"""),46102.0) -> 46102
...

Sheet (WIP) Dashboard v2
A1: Refer to Analyses Subsheet for source data

Sheet (WIP) Analysis
A1: Team Name | B1: Issue Type | C1: Issue Severity | D1: Date | E1: Assigned Week # | G1: Full Size Charts on Dashboard v2 | M1: Week # | N1: Num. Issues
A2: =#REF! -> #REF! | B2: =#REF! -> #REF! | C2: =#REF! -> #REF! | D2: =#REF! -> #REF! | E2: =WEEKNUM(D2)-38 -> #REF! | M2: 0 | N2: =COUNTIF(E2:E100, M2) -> 6
A3: =#REF! -> #REF! | B3: =#REF! -> #REF! | C3: =#REF! -> #REF! | D3: =#REF! -> #REF! | E3: =WEEKNUM(D3)-38 -> #REF! | M3: 1 | N3: =COUNTIF(E3:E101, M3) -> 0
A4: =#REF! -> #REF! | B4: =#REF! -> #REF! | C4: =#REF! -> #REF! | D4: =#REF! -> #REF! | E4: =WEEKNUM(D4)-38 -> #REF! | M4: 2 | N4: =COUNTIF(E4:E102, M4) -> 7
A5: =#REF! -> #REF! | B5: =#REF! -> #REF! | C5: =#REF! -> #REF! | D5: =#REF! -> #REF! | E5: =WEEKNUM(D5)-38 -> #REF! | M5: 3 | N5: =COUNTIF(E5:E103, M5) -> 0
A6: =#REF! -> #REF! | B6: =#REF! -> #REF! | C6: =#REF! -> #REF! | D6: =#REF! -> #REF! | E6: =WEEKNUM(D6)-38 -> #REF! | M6: 4 | N6: =COUNTIF(E6:E104, M6) -> 0
A7: =#REF! -> #REF! | B7: =#REF! -> #REF! | C7: =#REF! -> #REF! | D7: =#REF! -> #REF! | E7: =WEEKNUM(D7)-38 -> #REF! | M7: 5 | N7: =COUNTIF(E7:E105, M7) -> 0
A8: =#REF! -> #REF! | B8: =#REF! -> #REF! | C8: =#REF! -> #REF! | D8: =#REF! -> #REF! | E8: =WEEKNUM(D8)-38 -> #REF! | M8: 6 | N8: =COUNTIF(E8:E106, M8) -> 0
A9: ='Form Responses'!D2 -> steel bridge | B9: ='Form Responses'!G2 -> Housekeeping | C9: ='Form Responses'!E2 -> Yellow - Stewardship concern (Address at next scheduled meeting) | D9: ='Form Responses'!A2 -> 45918.389 | E9: =WEEKNUM(D9)-38 -> 0 | M9: 7 | N9: =COUNTIF(E9:E107, M9) -> 0
A10: ='Form Responses'!D3 -> concrete canoe | B10: ='Form Responses'!G3 -> Shared space (misuse of) | C10: ='Form Responses'!E3 -> Yellow - Stewardship concern (Address at next scheduled meeting) | D10: ='Form Responses'!A3 -> 45918.392 | E10: =WEEKNUM(D10)-38 -> 0 | M10: 8 | N10: =COUNTIF(E10:E108, M10) -> 0
A11: ='Form Responses'!D4 -> Formula | B11: ='Form Responses'!G4 -> Shared space (misuse of) | C11: ='Form Responses'!E4 -> Yellow - Stewardship concern (Address at next scheduled meeting) | D11: ='Form Responses'!A4 -> 45918.395 | E11: =WEEKNUM(D11)-38 -> 0 | M11: 9 | N11: =COUNTIF(E11:E109, M11) -> 0
A12: ='Form Responses'!D5 -> concrete canoe | B12: ='Form Responses'!G5 -> Housekeeping | C12: ='Form Responses'!E5 -> Yellow - Stewardship concern (Address at next scheduled meeting) | D12: ='Form Responses'!A5 -> 45918.398 | E12: =WEEKNUM(D12)-38 -> 0 | M12: 10 | N12: =COUNTIF(E12:E110, M12) -> 0
A13: ='Form Responses'!D6 -> Formula | B13: ='Form Responses'!G6 -> Shared space (misuse of) | C13: ='Form Responses'!E6 -> Orange - Operations/ Safety issue (resolve in 2-3 business days) | D13: ='Form Responses'!A6 -> 45918.621 | E13: =WEEKNUM(D13)-38 -> 0 | M13: 11 | N13: =COUNTIF(E13:E111, M13) -> 0
A14: ='Form Responses'!D7 -> concrete canoe | B14: ='Form Responses'!G7 -> Fire / electrical (code violation) | C14: ='Form Responses'!E7 -> Red - Code violation (immediate action Required) | D14: ='Form Responses'!A7 -> 45919.718 | E14: =WEEKNUM(D14)-38 -> 0 | M14: 12 | N14: =COUNTIF(E14:E112, M14) -> 0
A15: ='Form Responses'!D8 -> Mars Rover | B15: ='Form Responses'!G8 -> Egress / access | C15: ='Form Responses'!E8 -> Yellow - Stewardship concern (Address at next scheduled meeting) | D15: ='Form Responses'!A8 -> 45932.638 | E15: =WEEKNUM(D15)-38 -> 2 | M15: 13 | N15: =COUNTIF(E15:E113, M15) -> 0
A16: ='Form Responses'!D9 -> DEBUT | B16: ='Form Responses'!G9 -> Fire / electrical (code violation) | C16: ='Form Responses'!E9 -> Red - Code violation (immediate action Required) | D16: ='Form Responses'!A9 -> 45932.695 | E16: =WEEKNUM(D16)-38 -> 2 | M16: 14 | N16: =COUNTIF(E16:E114, M16) -> 0
A17: ='Form Responses'!D10 -> Operations Team | B17: ='Form Responses'!G10 -> Unsafe Work Practices | C17: ='Form Responses'!E10 -> Yellow - Stewardship concern (Address at next scheduled meeting) | D17: ='Form Responses'!A10 -> 45933.384 | E17: =WEEKNUM(D17)-38 -> 2 | M17: 15 | N17: =COUNTIF(E17:E115, M17) -> 0
A18: ='Form Responses'!D11 -> Operations Team | B18: ='Form Responses'!G11 -> Maintenance/ facilities | C18: ='Form Responses'!E11 -> Ivory - Below standard (demonstrate improvement in 14-21 days) | D18: ='Form Responses'!A11 -> 45933.396 | E18: =WEEKNUM(D18)-38 -> 2 | M18: 16 | N18: =COUNTIF(E18:E116, M18) -> 0
A19: ='Form Responses'!D12 -> Operations Team | B19: ='Form Responses'!G12 -> Unsafe Work Practices | C19: ='Form Responses'!E12 -> Yellow - Stewardship concern (Address at next scheduled meeting) | D19: ='Form Responses'!A12 -> 45933.398 | E19: =WEEKNUM(D19)-38 -> 2 | M19: 17 | N19: =COUNTIF(E19:E117, M19) -> 0
A20: ='Form Responses'!D13 -> Operations Team | B20: ='Form Responses'!G13 -> Fire / electrical (code violation) | C20: ='Form Responses'!E13 -> Yellow - Stewardship concern (Address at next scheduled meeting) | D20: ='Form Responses'!A13 -> 45933.399 | E20: =WEEKNUM(D20)-38 -> 2 | M20: 18 | N20: =COUNTIF(E20:E118, M20) -> 0
A21: ='Form Responses'!D14 -> Operations Team | B21: ='Form Responses'!G14 -> Maintenance/ facilities | C21: ='Form Responses'!E14 -> Purple - Opportunity for improvement (as time permits) | D21: ='Form Responses'!A14 -> 45933.403 | E21: =WEEKNUM(D21)-38 -> 2 | M21: 19 | N21: =COUNTIF(E21:E119, M21) -> 0
A22: ='Form Responses'!D105 | B22: ='Form Responses'!G105 | C22: ='Form Responses'!E105 | D22: ='Form Responses'!A105 | M22: 20 | N22: =COUNTIF(E22:E120, M22) -> 0
A23: ='Form Responses'!D106 | B23: ='Form Responses'!G106 | C23: ='Form Responses'!E106 | D23: ='Form Responses'!A106 | M23: 21 | N23: =COUNTIF(E23:E121, M23) -> 0
A24: ='Form Responses'!D107 | B24: ='Form Responses'!G107 | C24: ='Form Responses'!E107 | D24: ='Form Responses'!A107 | M24: 22 | N24: =COUNTIF(E24:E122, M24) -> 0
A25: ='Form Responses'!D108 | B25: ='Form Responses'!G108 | C25: ='Form Responses'!E108 | D25: ='Form Responses'!A108 | M25: 23 | N25: =COUNTIF(E25:E123, M25) -> 0
A26: ='Form Responses'!D109 | B26: ='Form Responses'!G109 | C26: ='Form Responses'!E109 | D26: ='Form Responses'!A109 | M26: 24 | N26: =COUNTIF(E26:E124, M26) -> 0
A27: ='Form Responses'!D110 | B27: ='Form Responses'!G110 | C27: ='Form Responses'!E110 | D27: ='Form Responses'!A110 | M27: 25 | N27: =COUNTIF(E27:E125, M27) -> 0
